<mujoco model="ur5e_hande_v2">
  <compiler angle="radian" meshdir="assets" autolimits="true"/>

  <option integrator="implicitfast" noslip_iterations="0" cone="elliptic" impratio="4" timestep="1e-5">
    <!-- <flag multiccd="enable"/> -->
  </option>

  <asset>
    <material class="ur5e" name="black" rgba="0.033 0.033 0.033 1"/>
    <material class="ur5e" name="jointgray" rgba="0.278 0.278 0.278 1"/>
    <material class="ur5e" name="linkgray" rgba="0.82 0.82 0.82 1"/>
    <material class="ur5e" name="urblue" rgba="0.49 0.678 0.8 1"/>
    <mesh file="base_0.obj"/><mesh file="base_1.obj"/>
    <mesh file="shoulder_0.obj"/><mesh file="shoulder_1.obj"/><mesh file="shoulder_2.obj"/>
    <mesh file="upperarm_0.obj"/><mesh file="upperarm_1.obj"/><mesh file="upperarm_2.obj"/><mesh file="upperarm_3.obj"/>
    <mesh file="forearm_0.obj"/><mesh file="forearm_1.obj"/><mesh file="forearm_2.obj"/><mesh file="forearm_3.obj"/>
    <mesh file="wrist1_0.obj"/><mesh file="wrist1_1.obj"/><mesh file="wrist1_2.obj"/>
    <mesh file="wrist2_0.obj"/><mesh file="wrist2_1.obj"/><mesh file="wrist2_2.obj"/>
    <mesh file="wrist3.obj"/>
    <mesh name="hande" file="hande.stl"/>
    <mesh name="coupler" file="coupler.stl"/>
    <mesh name="left_finger"  file="finger_2.stl"/>
    <mesh name="right_finger" file="finger_1.stl"/>
  </asset>

  <default>
    <default class="ur5e">
        <material specular="0.5" shininess="0.25"/>
        <joint axis="0 1 0" range="-6.28319 6.28319" armature="0.1"/>
        <general gaintype="fixed" biastype="affine" ctrlrange="-6.2831 6.2831" gainprm="2000" biasprm="0 -2000 -400" forcerange="-150 150"/>

        <default class="size3">
          <general gainprm="4500" biasprm="0 -4500 -450" forcerange="-87 87"/>
          <default class="size3_limited">
            <joint range="-3.1415 3.1415"/>
            <!-- <general ctrlrange="-3.1415 3.1415"/> -->
            <general ctrlrange="-3.1415 3.1415" gainprm="3500" biasprm="0 -3500 -350" forcerange="-87 87"/>
          </default>
        </default>

        <default class="size1">
          <!-- <general gainprm="500" biasprm="0 -500 -100" forcerange="-28 28"/> -->
          <general gainprm="2000" biasprm="0 -2000 -200" forcerange="-28 28"/>
        </default>

        <default class="visual">
          <geom type="mesh" contype="0" conaffinity="0" group="2"/>
        </default>

        <default class="collision">
          <geom type="capsule" group="3"/>
          <default class="eef_collision"><geom type="cylinder"/></default>
        </default>

        <default class="object_collision">
          <geom type="mesh" group="4" condim="6" friction="10 5e-1 1e-4"/>
        </default>

        <site size="0.001" rgba="0.5 0.5 0.5 0.3" group="4"/>

        <default class="hande_visual">
            <geom type="mesh" contype="0" conaffinity="0" group="2" rgba="0.6 0.6 0.6 1"/>

            <default class="finger_visual">
                <geom type="mesh" contype="0" conaffinity="0" group="2" rgba="0.6 0.6 0.6 1" pos="-0.025 0 0"/>

                <default class="fingertip_LR_visual_marker">
                  <geom type="box" size="0.0105 0.003 0.010" pos="0.003 0 0.0365" quat="1 0 0 1" group="5"/>
                </default>

            </default>
        </default>

        <default class="hande_collision">
            <geom group="3" condim="6" friction="10 5e-1 1e-4"/>
            <!--  -->
            <default class="hande_base">
                <geom type="cylinder" size="0.0375 0.05" pos="0 0 0.05"/>
            </default>

            <default class="finger">
                <joint axis="1 0 0" type="slide" range="0 0.025"/>
            </default>

            <default class="finger_base">
                <geom type="box" size="0.0105 0.0024 0.01325" pos="0.0084 0 0.01325" quat="1 0 0 1"/>
            </default>
            <default class="finger_connect">
                <geom type="box" size="0.0105 0.0054 0.002" pos="0.0054 0 0.0285" quat="1 0 0 1"/>
            </default>
            <default class="fingertip">
                <geom type="box" size="0.0105 0.003 0.010" pos="0.003 0 0.0365" quat="1 0 0 1"/>
            </default>
        </default>



      <default class="hande_site">
        <default class="canonical_fingertip_surafece_site">
          <site type="box" size="0.0105 0.003 0.010" rgba="1 1 0 0.5" pos="0 0 0.0365" quat="1 0 0 -1"/>
        </default>


      </default>

    </default>
  </default>

  <worldbody>
    <light name="spotlight" mode="targetbodycom" target="wrist_2_link" pos="0 -1 2"/>


    <body name="base" pos="-0.5 0 0" childclass="ur5e" quat="1 0 0 1">
      <inertial mass="4.0" pos="0 0 0" diaginertia="0.00443333156 0.00443333156 0.0072"/>
      <geom mesh="base_0" material="black" class="visual"/>
      <geom mesh="base_1" material="jointgray" class="visual"/>
      <body name="shoulder_link" pos="0 0 0.163">
        <inertial mass="3.7" pos="0 0 0" diaginertia="0.0102675 0.0102675 0.00666"/>
        <joint name="shoulder_pan_joint" class="size3" axis="0 0 1"/>
        <geom mesh="shoulder_0" material="urblue" class="visual"/>
        <geom mesh="shoulder_1" material="black" class="visual"/>
        <geom mesh="shoulder_2" material="jointgray" class="visual"/>
        <geom class="collision" size="0.06 0.06" pos="0 0 -0.04"/>
        <body name="upper_arm_link" pos="0 0.138 0" quat="1 0 1 0">
          <inertial mass="8.393" pos="0 0 0.2125" diaginertia="0.133886 0.133886 0.0151074"/>
          <joint name="shoulder_lift_joint" class="size3"/>
          <geom mesh="upperarm_0" material="linkgray" class="visual"/>
          <geom mesh="upperarm_1" material="black" class="visual"/>
          <geom mesh="upperarm_2" material="jointgray" class="visual"/>
          <geom mesh="upperarm_3" material="urblue" class="visual"/>
          <geom class="collision" pos="0 -0.04 0" quat="1 1 0 0" size="0.06 0.06"/>
          <geom class="collision" size="0.05 0.2" pos="0 0 0.2"/>
          <body name="forearm_link" pos="0 -0.131 0.425">
            <inertial mass="2.275" pos="0 0 0.196" diaginertia="0.0311796 0.0311796 0.004095"/>
            <joint name="elbow_joint" class="size3_limited"/>
            <geom mesh="forearm_0" material="urblue" class="visual"/>
            <geom mesh="forearm_1" material="linkgray" class="visual"/>
            <geom mesh="forearm_2" material="black" class="visual"/>
            <geom mesh="forearm_3" material="jointgray" class="visual"/>
            <geom class="collision" pos="0 0.08 0" quat="1 1 0 0" size="0.055 0.06"/>
            <geom class="collision" size="0.038 0.19" pos="0 0 0.2"/>
            <body name="wrist_1_link" pos="0 0 0.392" quat="1 0 1 0">
              <inertial mass="1.219" pos="0 0.127 0" diaginertia="0.0025599 0.0025599 0.0021942"/>
              <joint name="wrist_1_joint" class="size1"/>
              <geom mesh="wrist1_0" material="black" class="visual"/>
              <geom mesh="wrist1_1" material="urblue" class="visual"/>
              <geom mesh="wrist1_2" material="jointgray" class="visual"/>
              <geom class="collision" pos="0 0.05 0" quat="1 1 0 0" size="0.04 0.07"/>
              <body name="wrist_2_link" pos="0 0.127 0">
                <inertial mass="1.219" pos="0 0 0.1" diaginertia="0.0025599 0.0025599 0.0021942"/>
                <joint name="wrist_2_joint" axis="0 0 1" class="size1"/>
                <geom mesh="wrist2_0" material="black" class="visual"/>
                <geom mesh="wrist2_1" material="urblue" class="visual"/>
                <geom mesh="wrist2_2" material="jointgray" class="visual"/>
                <geom class="collision" size="0.04 0.06" pos="0 0 0.04"/>
                <geom class="collision" pos="0 0.02 0.1" quat="1 1 0 0" size="0.04 0.04"/>
                <body name="wrist_3_link" pos="0 0 0.1">
                  <inertial mass="0.1889" pos="0 0.0771683 0" quat="1 0 0 1" diaginertia="0.000132134 9.90863e-05 9.90863e-05"/>
                  <joint name="wrist_3_joint" class="size1"/>
                  <geom material="linkgray" mesh="wrist3" class="visual"/>
                  <geom class="eef_collision" pos="0 0.08 0" quat="1 1 0 0" size="0.04 0.02"/>

                  <!--  -->
                  <!-- <body name="hand" pos="0 0.1 0" quat="0.5 -0.5 -0.5 -0.5"> -->
                  <body name="hand" pos="0 0.1 0" quat="0.7071 -0.7071 -0.0000 -0.0000">
                      <geom class="hande_visual" mesh="coupler" rgba="0.1 0.1 0.1 1"/>
                      <geom class="hande_visual" mesh="hande"   rgba="0.1 0.1 0.1 1"/>
                      <geom class="hande_base"/>

                       <!-- canonical gripper surface -->
                      <body name="canonical_fingertip_surafece" pos="0 0 0.099">
                        <site class="canonical_fingertip_surafece_site" name="canonical_fingertip_surafece"/>
                      </body>

                      <body name="left_finger" pos="0 0 0.099">
                          <inertial pos="0.02262 -0.00759 0.00738" quat="0.871952 0.0369732 -0.211073 0.440205" mass="0.03804" diaginertia="1.22763e-05 1.22763e-05 1.22763e-05"/>
                          <joint name="finger_joint1" class="finger"/>
                          <!-- collision -->
                          <geom class="finger_base"    name="finger_base_left"       rgba="0 0.1 0 1"/>
                          <geom class="finger_connect" name="finger_connect_left"    rgba="0 0.2 0 1"/>
                          <geom class="fingertip"      name="left_fingertip_center"  rgba="0 0.6 0 1"/>
                          <!-- visual -->
                          <geom class="finger_visual" mesh="left_finger" quat="0 0 0 1"/>
                          <geom class="fingertip_LR_visual_marker" name="fingertip_left_visual_marker"  rgba="0 0.6 0 1"/>
                      </body>

                      <body name="right_finger" pos="0 0 0.099" quat="0 0 0 1">
                          <inertial pos="-0.02262 0.00759 0.00738" quat="0.871952 -0.0369732 0.211073 0.440205" mass="0.03804" diaginertia="1.22763e-05 1.22763e-05 1.22763e-05"/>
                          <joint name="finger_joint2" class="finger"/>
                          <!-- collision -->
                          <geom class="finger_base"    name="finger_base_right"      rgba="0.1 0 0 1"/>
                          <geom class="finger_connect" name="finger_connect_right"   rgba="0.2 0 0 1"/>
                          <geom class="fingertip"      name="right_fingertip_center" rgba="0.6 0 0 1"/>
                          <!-- visual -->
                          <geom class="finger_visual"   mesh="right_finger" />
                          <geom class="fingertip_LR_visual_marker" name="fingertip_right_visual_marker"  rgba="0.6 0 0 1"/>
                      </body>
                  </body>

                </body>
              </body>
            </body>
          </body>
        </body>
      </body>
    </body>
  </worldbody>

  <contact>
    <exclude body1="hand" body2="left_finger"/>
    <exclude body1="hand" body2="right_finger"/>
  </contact>

  <tendon>
    <fixed name="split">
      <joint joint="finger_joint1" coef="0.5"/>
      <joint joint="finger_joint2" coef="0.5"/>
    </fixed>
  </tendon>

  <equality>
    <joint joint1="finger_joint1" joint2="finger_joint2" solimp="0.95 0.99 0.001" solref="0.005 1"/>
  </equality>

  <actuator>
    <general class="size3"         name="shoulder_pan"  joint="shoulder_pan_joint"/>
    <general class="size3"         name="shoulder_lift" joint="shoulder_lift_joint"/>
    <general class="size3_limited" name="elbow"         joint="elbow_joint"/>
    <general class="size1"         name="wrist_1"       joint="wrist_1_joint"/>
    <general class="size1"         name="wrist_2"       joint="wrist_2_joint"/>
    <general class="size1"         name="wrist_3"       joint="wrist_3_joint"/>
    <!-- Remap original ctrlrange (0, 0.025) to (0, 255): 0.04 * 100 / 255 = 0.01568627451 -->
    <!-- <general name="actuator_finger" class="ur5e" tendon="split"
        ctrlrange="0 0.025" forcerange="-200 200" gaintype="affine" biastype="affine"
        gainprm="0.00980392156862745" biasprm="0 -100 -10"/> -->
    <general class="ur5e" name="actuator_finger" tendon="split" forcerange="-100 100" ctrlrange="0 0.025"
      gainprm="100 0 0" biasprm="0 -100 -10"/>
  </actuator>

  <keyframe>
    <key name="home" qpos="-1.5708 -1.5708 1.5708 -1.5708 -1.5708 0     0.025 0.025   0 0 0.196   1 0 0 0" ctrl="-1.5708 -1.5708 1.5708 -1.5708 -1.5708 0    0.025"/>
  </keyframe>
</mujoco>
